Workbook

Sheet Assumptions
A1: BU SERVICES — 2026 CONFERENCE BUDGET · ASSUMPTION INPUTS
A3: All blue cells are editable inputs. Black cells are formula-driven. Change any blue cell and the Budget Model updates automatically.
A4: SECTION 1 — PERSONNEL (Daily Unbillable Opportunity Cost)
A5: Average annual salary (CAD) | B5: 150000 | C5: Applies to all attending personnel
A6: Working days per year | B6: 235 | C6: Excludes weekends, statutory holidays, vacation
A7: Daily unbillable cost per person (CAD) | B7: =B5/B6 -> 638.29787 | C7: Formula: Annual salary ÷ working days
A8: Travel days (unbillable — per trip) | B8: 1.5 | C8: Avg 1.5 days travel per trip (flight + setup day)
A10: SECTION 2 — FLIGHTS FROM QUÉBEC CITY (YQB) — RETURN ECONOMY
A11: YQB → Calgary (YYC) return | B11: 620 | C11: Air Canada / WestJet — approx via Montreal or Toronto | I11: w
A12: YQB → Toronto (YYZ) return | B12: 380 | C12: Short haul — direct or 1-stop
A13: YQB → Vancouver (YVR) return | B13: 720 | C13: Via Toronto or Montreal hub
A14: YQB → Chicago (ORD) return | B14: 680 | C14: Via Toronto or Montreal — USD fare × 1.38
A15: YQB → Houston (IAH/HOU) return | B15: 820 | C15: Via Toronto or Montreal hub
A16: YQB → Las Vegas (LAS) return | B16: 750 | C16: Via Toronto or Montreal hub
A17: YQB → San Antonio (SAT) return | B17: 880 | C17: Via Houston or Dallas hub
A18: YQB → Austin (AUS) return | B18: 860 | C18: Via Houston or Dallas hub
A19: YQB → Columbus (CMH) return | B19: 780 | C19: Via Toronto or Montreal hub
A20: YQB → Timmins (YTS) return | B20: 580 | C20: Via Toronto — regional connection
A21: YQB → Thunder Bay (YQT) return | B21: 560 | C21: Via Toronto — regional connection
A22: YQB → Halifax (YHZ) return | B22: 340 | C22: Short haul — direct or 1-stop
A23: YQB → Paris (CDG) return | B23: 1850 | C23: Air France / Air Canada — economy
... A25: YQB → Verona/Milan (MXP) return | B25: 1900 | C25: Via Paris or Frankfurt — economy
A27: SECTION 3 — HOTEL (PER NIGHT, PER PERSON, CAD)
A28: Canada — major city (Calgary, Ottawa, Vancouver) | B28: 260 | C28: Per night per room
A29: Canada — regional (Timmins, Thunder Bay, Halifax) | B29: 185 | C29: Per night per room
A30: USA — major city (Houston, Chicago, Las Vegas) | B30: 295 | C30: Per night per room — USD × 1.38
A31: USA — conference hotel premium (San Antonio, Columbus) | B31: 310 | C31: Convention center hotels command premium
A32: Europe — major city (Paris, Lyon, Verona) | B32: 310 | C32: Per night per room — EUR × 1.52
A34: SECTION 4 — DAILY EXPENSES (MEALS, LOCAL TRANSPORT, INCIDENTALS)
A35: Canada — daily expenses per person | B35: 120 | C35: Meals + local transport + incidentals
A36: USA — daily expenses per person | B36: 165 | C36: USD equivalent — meals, Uber, incidentals
A37: Europe — daily expenses per person | B37: 195 | C37: EUR equivalent — meals, metro, incidentals
A39: SECTION 5 — BOOTH & EXHIBIT COSTS (UPDATE FROM PROSPECTUS WHERE AVAILABLE)
A40: ⚠ Booth space fees vary significantly by show. Cells below are estimates — replace with actual prospectus figures when available. Drayage (material handling) is often the most underestimated line — budget 20-30% of space fee for major US shows.
A41: Item | B41: Cost (CAD) | C41: Notes | D41: Source
A42: Booth space fee — 10×10 / 9sqm Canada | B42: 4500 | C42: IPEIA, IPC, IPCE approx | D42: Estimate — verify with show prospectus
A43: Booth space fee — 10×10 / 9sqm USA (small show) | B43: 5500 | C43: NDTMA, PPIM, AMPP tabletop | D43: Estimate — verify with show prospectus
A44: Booth space fee — 10×10 / 9sqm USA (major show) | B44: 8500 | C44: API Inspection Summit, API Storage Tank | D44: Estimate — verify with show prospectus
A45: Booth space fee — ASNT 400sqft (20×20) | B45: 18000 | C45: ASNT Columbus — largest NDT show N.America | D45: Estimate — verify with ASNT 2026 prospectus
A46: Booth space fee — ECNDT 36sqm | B46: 12000 | C46: ECNDT Verona — 6×6m | D46: Estimate — verify with ECNDT 2026 prospectus
...

Sheet Budget Model
A1: BU SERVICES — 2026 CONFERENCE BUDGET MODEL | Québec City (YQB) departure base | $180K avg salary assumption
A3: Blue cells = editable inputs. Black = formula. Personnel cost = daily unbillable rate × (conference days + travel days). Booth costs from Assumptions sheet — update from prospectus. All amounts CAD.
A4: Conference | B4: Priority | C4: Region | D4: # People | E4: Conf Days | F4: ✈ Flights (CAD) | G4: 🏨 Hotel (CAD) | H4: 🍽 Expenses (CAD) | I4: 👤 Personnel Unbillable | J4: 📦 Booth Space Fee | K4: 🔧 Drayage & Services | L4: 🚚 Freight & Materials | M4: 📋 Regist- ration | N4: TOTAL COST (CAD) | O4: Cost per Person | P4: Key Attendees | Q4: Initiative Link | R4: Boost Score
F5: YQB return fares | G5: Nightly rate × nights | H5: Daily rate × days | I5: Salary cost of time away from billing | J5: Space fee from prospectus | K5: Drayage + elec + furniture | L5: Freight + printed materials | M5: Conference passes (if not in booth pkg)
A6: IPEIA 2026 | B6: HIGH | C6: Canada | D6: 6 | E6: 3 | F6: =D6*Assumptions!$B$11 -> 3720 | G6: =D6*4*Assumptions!$B$28 -> 6240 | H6: =D6*(E6+Assumptions!$B$8)*Assumptions!$B$35 -> 3240 | I6: =D6*(E6+Assumptions!$B$8)*Assumptions!$B$7 -> 17234.043 | J6: =Assumptions!$B$42 -> 4500 | K6: =Assumptions!$B$48+Assumptions!$B$51+Assumptions!$B$52 -> 2350 | L6: =Assumptions!$B$53*2+Assumptions!$B$55 -> 2300 | M6: =Assumptions!$B$56 -> 1800 | N6: =SUM(F6:M6) -> 41384.043 | O6: =IF(D6>0,N6/D6,0) -> 6897.3404 | P6: Max · Keith · Tim · Alex · Rick · Marcos | Q6: Pipeline DA · Nuclear · Mining · Base Biz | R6: 9.2
A7: CNA 2026 | B7: HIGH | C7: Canada | D7: 4 | E7: 3 | F7: =D7*Assumptions!$B$11 -> 2480 | G7: =D7*4*Assumptions!$B$28 -> 4160 | H7: =D7*(E7+Assumptions!$B$8)*Assumptions!$B$35 -> 2160 | I7: =D7*(E7+Assumptions!$B$8)*Assumptions!$B$7 -> 11489.362 | J7: 0 | K7: 0 | L7: =Assumptions!$B$55 -> 600 | M7: =Assumptions!$B$56 -> 1800 | N7: =SUM(F7:M7) -> 22689.362 | O7: =IF(D7>0,N7/D7,0) -> 5672.3404 | P7: Oli · Jon · LP · Sha | Q7: Nuclear/OPG — regulatory relationships | R7: 8.8
A8: IPC Pipeline Conf. | B8: HIGH | C8: Canada | D8: 2 | E8: 5 | F8: =D8*Assumptions!$B$11 -> 1240 | G8: =D8*6*Assumptions!$B$28 -> 3120 | H8: =D8*(E8+Assumptions!$B$8)*Assumptions!$B$35 -> 1560 | I8: =D8*(E8+Assumptions!$B$8)*Assumptions!$B$7 -> 8297.8723 | J8: =Assumptions!$B$42 -> 4500 | K8: =Assumptions!$B$48+Assumptions!$B$51+Assumptions!$B$52 -> 2350 | L8: =Assumptions!$B$53*2+Assumptions!$B$55 -> 2300 | M8: =Assumptions!$B$56 -> 1800 | N8: =SUM(F8:M8) -> 25167.872 | O8: =IF(D8>0,N8/D8,0) -> 12583.936 | P8: Max · Vinoth | Q8: Pipeline DA · $30M initiative | R8: 8.5
A9: PPIM 2026 | B9: HIGH | C9: USA | D9: 3 | E9: 4 | F9: =D9*Assumptions!$B$15 -> 2460 | G9: =D9*5*Assumptions!$B$30 -> 4425 | H9: =D9*(E9+Assumptions!$B$8)*Assumptions!$B$36 -> 2722.5 | I9: =D9*(E9+Assumptions!$B$8)*Assumptions!$B$7 -> 10531.915 | J9: =Assumptions!$B$43 -> 5500 | K9: =Assumptions!$B$49+Assumptions!$B$51+Assumptions!$B$52 -> 3750 | L9: =Assumptions!$B$53*2+Assumptions!$B$55 -> 2300 | M9: =Assumptions!$B$56 -> 1800 | N9: =SUM(F9:M9) -> 33489.415 | O9: =IF(D9>0,N9/D9,0) -> 11163.138 | P9: Jeff · Anthony · Aaron | Q9: Pipeline DA · US market | R9: 8.2
A10: NDTMA 2026 | B10: HIGH | C10: USA | D10: 5 | E10: 3 | F10: =D10*Assumptions!$B$16 -> 3750 | G10: =D10*4*Assumptions!$B$30 -> 5900 | H10: =D10*(E10+Assumptions!$B$8)*Assumptions!$B$36 -> 3712.5 | I10: =D10*(E10+Assumptions!$B$8)*Assumptions!$B$7 -> 14361.702 | J10: =Assumptions!$B$43 -> 5500 | K10: =Assumptions!$B$49+Assumptions!$B$51+Assumptions!$B$52 -> 3750 | L10: =Assumptions!$B$53*2+Assumptions!$B$55 -> 2300 | M10: =Assumptions!$B$56 -> 1800 | N10: =SUM(F10:M10) -> 41074.202 | O10: =IF(D10>0,N10/D10,0) -> 8214.8404 | P10: Dillon · Jeff · Fred · Guillaume · Anthony | Q10: Mining NDT · Nuclear · Base Business | R10: 7.8
A11: AMPP 2026 | B11: HIGH | C11: USA | D11: 2 | E11: 5 | F11: =D11*Assumptions!$B$15 -> 1640 | G11: =D11*6*Assumptions!$B$30 -> 3540 | H11: =D11*(E11+Assumptions!$B$8)*Assumptions!$B$36 -> 2145 | I11: =D11*(E11+Assumptions!$B$8)*Assumptions!$B$7 -> 8297.8723 | J11: =Assumptions!$B$43 -> 5500 | K11: =Assumptions!$B$49+Assumptions!$B$51+Assumptions!$B$52 -> 3750 | L11: =Assumptions!$B$53*2+Assumptions!$B$55 -> 2300 | M11: =Assumptions!$B$56 -> 1800 | N11: =SUM(F11:M11) -> 28972.872 | O11: =IF(D11>0,N11/D11,0) -> 14486.436 | P11: Vincent Ribouleau | Q11: Pipeline DA · 3X Composite · Base Biz | R11: 7.5
A12: API Inspection Summit | B12: HIGH | C12: USA | D12: 3 | E12: 4 | F12: =D12*Assumptions!$B$17 -> 2640 | G12: =D12*5*Assumptions!$B$31 -> 4650 | H12: =D12*(E12+Assumptions!$B$8)*Assumptions!$B$36 -> 2722.5 | I12: =D12*(E12+Assumptions!$B$8)*Assumptions!$B$7 -> 10531.915 | J12: =Assumptions!$B$44 -> 8500 | K12: =Assumptions!$B$49+Assumptions!$B$51+Assumptions!$B$52 -> 3750 | L12: =Assumptions!$B$53*2+Assumptions!$B$55 -> 2300 | M12: =Assumptions!$B$56 -> 1800 | N12: =SUM(F12:M12) -> 36894.415 | O12: =IF(D12>0,N12/D12,0) -> 12298.138 | P12: Keith · Tim · Alex | Q12: Pipeline DA · Base Biz · 3X | R12: 8
A13: ECNDT Verona | B13: HIGH | C13: Europe | D13: 5 | E13: 5 | F13: =D13*Assumptions!$B$25 -> 9500 | G13: =D13*6*Assumptions!$B$32 -> 9300 | H13: =D13*(E13+Assumptions!$B$8)*Assumptions!$B$37 -> 6337.5 | I13: =D13*(E13+Assumptions!$B$8)*Assumptions!$B$7 -> 20744.681 | J13: =Assumptions!$B$46 -> 12000 | K13: =Assumptions!$B$50+Assumptions!$B$51+Assumptions!$B$52 -> 2750 | L13: =Assumptions!$B$54*2+Assumptions!$B$55 -> 5000 | M13: =Assumptions!$B$57 -> 3500 | N13: =SUM(F13:M13) -> 69132.181 | O13: =IF(D13>0,N13/D13,0) -> 13826.436 | P13: Xavier · Guillaume · Lucy · Hervé · Fabian | Q13: All initiatives · Base Business | R13: 8.5
A14: ASNT 2026 | B14: HIGH | C14: USA | D14: 4 | E14: 4 | F14: =D14*Assumptions!$B$19 -> 3120 | G14: =D14*5*Assumptions!$B$31 -> 6200 | H14: =D14*(E14+Assumptions!$B$8)*Assumptions!$B$36 -> 3630 | I14: =D14*(E14+Assumptions!$B$8)*Assumptions!$B$7 -> 14042.553 | J14: =Assumptions!$B$45 -> 18000 | K14: =Assumptions!$B$49+Assumptions!$B$51+Assumptions!$B$52 -> 3750 | L14: =Assumptions!$B$53*2+Assumptions!$B$55 -> 2300 | M14: =Assumptions!$B$57 -> 3500 | N14: =SUM(F14:M14) -> 54542.553 | O14: =IF(D14>0,N14/D14,0) -> 13635.638 | P14: TBD ×4 | Q14: Mining NDT · Nuclear · Base Business | R14: 8.5
A15: IPCE Pipeline Expo | B15: HIGH | C15: Canada | D15: 2 | E15: 3 | F15: =D15*Assumptions!$B$11 -> 1240 | G15: =D15*4*Assumptions!$B$28 -> 2080 | H15: =D15*(E15+Assumptions!$B$8)*Assumptions!$B$35 -> 1080 | I15: =D15*(E15+Assumptions!$B$8)*Assumptions!$B$7 -> 5744.6809 | J15: =Assumptions!$B$42 -> 4500 | K15: =Assumptions!$B$48+Assumptions!$B$51+Assumptions!$B$52 -> 2350 | L15: =Assumptions!$B$53*2+Assumptions!$B$55 -> 2300 | M15: =Assumptions!$B$56 -> 1800 | N15: =SUM(F15:M15) -> 21094.681 | O15: =IF(D15>0,N15/D15,0) -> 10547.34 | P15: Vincent Ribouleau | Q15: Pipeline DA | R15: 7.8
A16: API Storage Tank Expo | B16: MED-H | C16: USA | D16: 2 | E16: 4 | F16: =D16*Assumptions!$B$18 -> 1720 | G16: =D16*5*Assumptions!$B$31 -> 3100 | H16: =D16*(E16+Assumptions!$B$8)*Assumptions!$B$36 -> 1815 | I16: =D16*(E16+Assumptions!$B$8)*Assumptions!$B$7 -> 7021.2766 | J16: =Assumptions!$B$44 -> 8500 | K16: =Assumptions!$B$49+Assumptions!$B$51+Assumptions!$B$52 -> 3750 | L16: =Assumptions!$B$53*2+Assumptions!$B$55 -> 2300 | M16: =Assumptions!$B$56 -> 1800 | N16: =SUM(F16:M16) -> 30006.277 | O16: =IF(D16>0,N16/D16,0) -> 15003.138 | P16: Keith · Tim | Q16: Pipeline DA · Base Biz · 3X | R16: 6.8
A17: API Insp. Summit (EIG) | B17: MED-H | C17: USA | D17: 2 | E17: 3 | F17: =D17*Assumptions!$B$17 -> 1760 | G17: =D17*4*Assumptions!$B$31 -> 2480 | H17: =D17*(E17+Assumptions!$B$8)*Assumptions!$B$36 -> 1485 | I17: =D17*(E17+Assumptions!$B$8)*Assumptions!$B$7 -> 5744.6809 | J17: =Assumptions!$B$44 -> 8500 | K17: =Assumptions!$B$49+Assumptions!$B$51+Assumptions!$B$52 -> 3750 | L17: =Assumptions!$B$55 -> 600 | M17: =Assumptions!$B$56 -> 1800 | N17: =SUM(F17:M17) -> 26119.681 | O17: =IF(D17>0,N17/D17,0) -> 13059.84 | P17: TBD ×2 (coordinate w/ Ekoscan) | Q17: Pipeline DA · Base Business | R17: 6.8
A18: CIM Vancouver | B18: MED | C18: Canada | D18: 2 | E18: 3 | F18: =D18*Assumptions!$B$13 -> 1440 | G18: =D18*3*Assumptions!$B$28 -> 1560 | H18: =D18*(E18+Assumptions!$B$8)*Assumptions!$B$35 -> 1080 | I18: =D18*(E18+Assumptions!$B$8)*Assumptions!$B$7 -> 5744.6809 | J18: 0 | K18: 0 | L18: =Assumptions!$B$55 -> 600 | M18: 0 | N18: =SUM(F18:M18) -> 10424.681 | O18: =IF(D18>0,N18/D18,0) -> 5212.3404 | P18: Vinoth · Max (walkin) | Q18: Mining NDT · $17.9M initiative | R18: 5.5
A19: Canadian Mining Expo | B19: MED | C19: Canada | D19: 2 | E19: 3 | F19: =D19*Assumptions!$B$20 -> 1160 | G19: =D19*3*Assumptions!$B$29 -> 1110 | H19: =D19*(E19+Assumptions!$B$8)*Assumptions!$B$35 -> 1080 | I19: =D19*(E19+Assumptions!$B$8)*Assumptions!$B$7 -> 5744.6809 | J19: =Assumptions!$B$42 -> 4500 | K19: =Assumptions!$B$48+Assumptions!$B$51+Assumptions!$B$52 -> 2350 | L19: =Assumptions!$B$53*2+Assumptions!$B$55 -> 2300 | M19: =Assumptions!$B$56 -> 1800 | N19: =SUM(F19:M19) -> 20044.681 | O19: =IF(D19>0,N19/D19,0) -> 10022.34 | P19: Keith · Speaker TBC | Q19: Mining NDT · 3X Composite | R19: 5.8
A20: T&D Conference | B20: MED | C20: USA | D20: 2 | E20: 4 | F20: =D20*Assumptions!$B$14 -> 1360 | G20: =D20*5*Assumptions!$B$30 -> 2950 | H20: =D20*(E20+Assumptions!$B$8)*Assumptions!$B$36 -> 1815 | I20: =D20*(E20+Assumptions!$B$8)*Assumptions!$B$7 -> 7021.2766 | J20: 0 | K20: 0 | L20: =Assumptions!$B$55 -> 600 | M20: =Assumptions!$B$56 -> 1800 | N20: =SUM(F20:M20) -> 15546.277 | O20: =IF(D20>0,N20/D20,0) -> 7773.1383 | P20: Math · Sha | Q20: Powerline · $10.2M initiative | R20: 5.5
A21: COFREND Lyon | B21: MED | C21: Europe | D21: 6 | E21: 3 | F21: =D21*Assumptions!$B$24 -> 11700 | G21: =D21*4*Assumptions!$B$32 -> 7440 | H21: =D21*(E21+Assumptions!$B$8)*Assumptions!$B$37 -> 5265 | I21: =D21*(E21+Assumptions!$B$8)*Assumptions!$B$7 -> 17234.043 | J21: =Assumptions!$B$47 -> 14000 | K21: =Assumptions!$B$50+Assumptions!$B$51+Assumptions!$B$52 -> 2750 | L21: =Assumptions!$B$54*2+Assumptions!$B$55 -> 5000 | M21: =Assumptions!$B$56 -> 1800 | N21: =SUM(F21:M21) -> 65189.043 | O21: =IF(D21>0,N21/D21,0) -> 10864.84 | P21: Guillaume N · Guillaume P · Michael · Sanae · Didier · Samy | Q21: Base Business · All initiatives | R21: 6.2
A22: Cigre Paris | B22: MED | C22: Europe | D22: 2 | E22: 6 | F22: =D22*Assumptions!$B$23 -> 3700 | G22: =D22*7*Assumptions!$B$32 -> 4340 | H22: =D22*(E22+Assumptions!$B$8)*Assumptions!$B$37 -> 2925 | I22: =D22*(E22+Assumptions!$B$8)*Assumptions!$B$7 -> 9574.4681 | J22: 0 | K22: 0 | L22: =Assumptions!$B$55 -> 600 | M22: =Assumptions!$B$57 -> 3500 | N22: =SUM(F22:M22) -> 24639.468 | O22: =IF(D22>0,N22/D22,0) -> 12319.734 | P22: Math +1 | Q22: Powerline · EIG group alignment | R22: 5.2
A23: CEN CAN Expo | B23: MED | C23: Canada | D23: 2 | E23: 2 | F23: =D23*Assumptions!$B$21 -> 1120 | G23: =D23*2*Assumptions!$B$29 -> 740 | H23: =D23*(E23+Assumptions!$B$8)*Assumptions!$B$35 -> 840 | I23: =D23*(E23+Assumptions!$B$8)*Assumptions!$B$7 -> 4468.0851 | J23: =Assumptions!$B$42 -> 4500 | K23: =Assumptions!$B$48+Assumptions!$B$51+Assumptions!$B$52 -> 2350 | L23: =Assumptions!$B$53*2+Assumptions!$B$55 -> 2300 | M23: =Assumptions!$B$56 -> 1800 | N23: =SUM(F23:M23) -> 18118.085 | O23: =IF(D23>0,N23/D23,0) -> 9059.0426 | P23: TBD ×2 | Q23: Mining NDT · Ontario mining sector | R23: 5
A24: Smart Energy Halifax | B24: LOW | C24: Canada | D24: 3 | E24: 2 | F24: =D24*Assumptions!$B$22 -> 1020 | G24: =D24*2*Assumptions!$B$29 -> 1110 | H24: =D24*(E24+Assumptions!$B$8)*Assumptions!$B$35 -> 1260 | I24: =D24*(E24+Assumptions!$B$8)*Assumptions!$B$7 -> 6702.1277 | J24: 0 | K24: 0 | L24: =Assumptions!$B$55 -> 600 | M24: 0 | N24: =SUM(F24:M24) -> 10692.128 | O24: =IF(D24>0,N24/D24,0) -> 3564.0426 | P24: Alex · Eric · Vinoth (walkin) | Q24: Powerline · Base Business | R24: 4.2
A26: SUBTOTAL — High Priority | F26: =SUMPRODUCT((B6:B24="HIGH")*F6:F24) -> 31790 | G26: =SUMPRODUCT((B6:B24="HIGH")*G6:G24) -> 49615 | H26: =SUMPRODUCT((B6:B24="HIGH")*H6:H24) -> 29310 | I26: =SUMPRODUCT((B6:B24="HIGH")*I6:I24) -> 121276.6 | J26: =SUMPRODUCT((B6:B24="HIGH")*J6:J24) -> 68500 | K26: =SUMPRODUCT((B6:B24="HIGH")*K6:K24) -> 28550 | L26: =SUMPRODUCT((B6:B24="HIGH")*L6:L24) -> 24000 | M26: =SUMPRODUCT((B6:B24="HIGH")*M6:M24) -> 21400 | N26: =SUMPRODUCT((B6:B24="HIGH")*N6:N24) -> 374441.6
A27: SUBTOTAL — Medium-High | F27: =SUMPRODUCT((B6:B24="MED-H")*F6:F24) -> 3480 | G27: =SUMPRODUCT((B6:B24="MED-H")*G6:G24) -> 5580 | H27: =SUMPRODUCT((B6:B24="MED-H")*H6:H24) -> 3300 | I27: =SUMPRODUCT((B6:B24="MED-H")*I6:I24) -> 12765.957 | J27: =SUMPRODUCT((B6:B24="MED-H")*J6:J24) -> 17000 | K27: =SUMPRODUCT((B6:B24="MED-H")*K6:K24) -> 7500 | L27: =SUMPRODUCT((B6:B24="MED-H")*L6:L24) -> 2900 | M27: =SUMPRODUCT((B6:B24="MED-H")*M6:M24) -> 3600 | N27: =SUMPRODUCT((B6:B24="MED-H")*N6:N24) -> 56125.957
A28: SUBTOTAL — Medium | F28: =SUMPRODUCT((B6:B24="MED")*F6:F24) -> 20480 | G28: =SUMPRODUCT((B6:B24="MED")*G6:G24) -> 18140 | H28: =SUMPRODUCT((B6:B24="MED")*H6:H24) -> 13005 | I28: =SUMPRODUCT((B6:B24="MED")*I6:I24) -> 49787.234 | J28: =SUMPRODUCT((B6:B24="MED")*J6:J24) -> 23000 | K28: =SUMPRODUCT((B6:B24="MED")*K6:K24) -> 7450 | L28: =SUMPRODUCT((B6:B24="MED")*L6:L24) -> 11400 | M28: =SUMPRODUCT((B6:B24="MED")*M6:M24) -> 10700 | N28: =SUMPRODUCT((B6:B24="MED")*N6:N24) -> 153962.23
A29: SUBTOTAL — Low / Walkin | F29: =SUMPRODUCT((B6:B24="LOW")*F6:F24) -> 1020 | G29: =SUMPRODUCT((B6:B24="LOW")*G6:G24) -> 1110 | H29: =SUMPRODUCT((B6:B24="LOW")*H6:H24) -> 1260 | I29: =SUMPRODUCT((B6:B24="LOW")*I6:I24) -> 6702.1277 | J29: =SUMPRODUCT((B6:B24="LOW")*J6:J24) -> 0 | K29: =SUMPRODUCT((B6:B24="LOW")*K6:K24) -> 0 | L29: =SUMPRODUCT((B6:B24="LOW")*L6:L24) -> 600 | M29: =SUMPRODUCT((B6:B24="LOW")*M6:M24) -> 0 | N29: =SUMPRODUCT((B6:B24="LOW")*N6:N24) -> 10692.128
A30: TOTAL 2026 CONFERENCE BUDGET — BU SERVICES (CAD) | F30: =SUM(F6:F24) -> 56770 | G30: =SUM(G6:G24) -> 74445 | H30: =SUM(H6:H24) -> 46875 | I30: =SUM(I6:I24) -> 190531.91 | J30: =SUM(J6:J24) -> 108500 | K30: =SUM(K6:K24) -> 43500 | L30: =SUM(L6:L24) -> 38900 | M30: =SUM(M6:M24) -> 35700 | N30: =SUM(N6:N24) -> 595221.91
F31: Flights | G31: Hotels | H31: Expenses | I31: Personnel Opport. Cost | J31: Booth Space | K31: Drayage & Services | L31: Freight & Materials | M31: Registration | N31: GRAND TOTAL
A33: 💡 PERSONNEL UNBILLABLE COST (Col I) reflects the salary cost of having staff away from revenue-generating work. Based on $180K avg annual salary ÷ 235 working days = $766/person/day. This is the true opportunity cost — it does NOT mean staff are paid extra, but that $766/day of potential billable time is lost per person per day away. Include this when comparing conference ROI vs other growth investments. Travel days (1.5 avg per trip) are included in the calculation.

Sheet Strategic Summary
A1: BU SERVICES — CONFERENCE STRATEGY · KEY RECOMMENDATIONS 2026
A3: INITIATIVE → CONFERENCE COVERAGE MAP
A4: Initiative | B4: 5yr Target | C4: Primary Conferences | D4: Owner | E4: Coverage Gap?
A5: Mining NDT | B5: $17.9M | C5: NDTMA · ECNDT · ASNT · Canadian Mining Expo · CIM Vancouver · CEN CAN Expo | F5: Vinoth / Max | G5: PARTIAL — CIM on waitlist
A6: Pipeline DA | B6: $30.0M | C6: PPIM · IPEIA · IPC Pipeline · IPCE · AMPP · API Inspection · API Storage Tank | F6: Rick Carlton | G6: GOOD — 7 shows
A7: Powerline | B7: $10.2M | C7: T&D Conference Chicago · Cigre Paris · Smart Energy Halifax | F7: Mathieu / Max | G7: WEAK — only 1 dedicated show
A8: Nuclear / OPG | B8: $47.9M | C8: CNA Ottawa · IPEIA · NDTMA · ECNDT Verona | F8: Olivier / Vinoth | G8: WEAK — largest initiative, fewest shows
A9: 3X Composite | B9: $11.4M | C9: AMPP · API Inspection Summit · API Storage Tank · ECNDT · IPEIA | F9: Vinoth / Max | G9: EMBEDDED — no standalone show needed
A10: Base Business | B10: Ongoing | C10: IPEIA · NDTMA · AMPP · ECNDT · ASNT · All API shows | F10: Full team | G10: GOOD
A13: BUDGET SNAPSHOT — COST CATEGORY BREAKDOWN
A14: Category | B14: HIGH Priority | C14: MED-HIGH | D14: MEDIUM | E14: LOW | F14: TOTAL
A15: ✈ Flights | B15: ='Budget Model'!F26 -> 31790 | C15: ='Budget Model'!F27 -> 3480 | D15: ='Budget Model'!F28 -> 20480 | E15: ='Budget Model'!F29 -> 1020 | F15: ='Budget Model'!F30 -> 56770
A16: 🏨 Hotel | B16: ='Budget Model'!G26 -> 49615 | C16: ='Budget Model'!G27 -> 5580 | D16: ='Budget Model'!G28 -> 18140 | E16: ='Budget Model'!G29 -> 1110 | F16: ='Budget Model'!G30 -> 74445
A17: 🍽 Expenses | B17: ='Budget Model'!H26 -> 29310 | C17: ='Budget Model'!H27 -> 3300 | D17: ='Budget Model'!H28 -> 13005 | E17: ='Budget Model'!H29 -> 1260 | F17: ='Budget Model'!H30 -> 46875
A18: 👤 Personnel Unbillable | B18: ='Budget Model'!I26 -> 121276.6 | C18: ='Budget Model'!I27 -> 12765.957 | D18: ='Budget Model'!I28 -> 49787.234 | E18: ='Budget Model'!I29 -> 6702.1277 | F18: ='Budget Model'!I30 -> 190531.91
A19: 📦 Booth Space | B19: ='Budget Model'!J26 -> 68500 | C19: ='Budget Model'!J27 -> 17000 | D19: ='Budget Model'!J28 -> 23000 | E19: ='Budget Model'!J29 -> 0 | F19: ='Budget Model'!J30 -> 108500
A20: 🔧 Drayage & Services | B20: ='Budget Model'!K26 -> 28550 | C20: ='Budget Model'!K27 -> 7500 | D20: ='Budget Model'!K28 -> 7450 | E20: ='Budget Model'!K29 -> 0 | F20: ='Budget Model'!K30 -> 43500
A21: 🚚 Freight & Materials | B21: ='Budget Model'!L26 -> 24000 | C21: ='Budget Model'!L27 -> 2900 | D21: ='Budget Model'!L28 -> 11400 | E21: ='Budget Model'!L29 -> 600 | F21: ='Budget Model'!L30 -> 38900
A22: 📋 Registration | B22: ='Budget Model'!M26 -> 21400 | C22: ='Budget Model'!M27 -> 3600 | D22: ='Budget Model'!M28 -> 10700 | E22: ='Budget Model'!M29 -> 0 | F22: ='Budget Model'!M30 -> 35700
A23: TOTAL | B23: ='Budget Model'!N26 -> 374441.6 | C23: ='Budget Model'!N27 -> 56125.957 | D23: ='Budget Model'!N28 -> 153962.23 | E23: ='Budget Model'!N29 -> 10692.128 | F23: ='Budget Model'!N30 -> 595221.91
A26: KEY RECOMMENDATIONS & ACTION ITEMS
A27: 🔴 ACTION NOW | B27: Coordinate API Inspection Summit — Nucleom and Ekoscan BU attending separately. Combine booth, split cost. Saves ~$12,000.
A28: 🔴 ACTION NOW | B28: Pursue Canadian Mining Expo waitlist aggressively — waitlist + speaker slot dramatically improves Mining NDT credibility with Timmins-area operators.
A29: 🟡 GAP | B29: Nuclear/OPG ($47.9M) is the largest initiative but has only 2 dedicated shows (CNA + IPEIA). Consider adding a CANDU Owners Group or OPG-specific stakeholder event.
A30: 🟡 GAP | B30: Powerline initiative ($10.2M) has only T&D Chicago as a dedicated show. Add one Canadian utility event (Hydro One forum, CEATI conference) to strengthen.
A31: 🟢 STRENGTH | B31: Pipeline DA has excellent coverage across 7 shows. Rick Carlton should lead messaging consistency across PPIM → AMPP → IPC → IPCE → both API shows.
A32: 🟢 STRENGTH | B32: IPEIA Calgary is your single highest-ROI event — all 5 initiatives + base business + all key personnel. Treat as anchor event for yearly commercial planning.
A33: 💡 INSIGHT | B33: Personnel unbillable cost (~$766/day/person) is your largest hidden cost. A 6-person team at a 3-day show = $13,800 in opportunity cost alone — before flights or hotels.
A34: 💡 INSIGHT | B34: SKIP Asia Pacific NDT (Honolulu) — $12K travel cost, zero North America commercial return. Redirect budget to Nuclear initiative prospecting or Powerline gap show.
A35: 💡 INSIGHT | B35: COFREND Lyon (11 people × 3 days) is the most expensive single event on personnel cost alone ($25,000+). Confirm which EIG-side attendees are truly necessary for BU Services objectives.
