Workbook

Sheet How To Use
A1: BU SERVICES — 2026 CONFERENCE ACTION TRACKER · HOW TO USE THIS WORKBOOK
A3: This workbook is the operational backbone of the BU Services 2026 conference programme. It works alongside the HTML Conference Action Plan portal. Read this sheet before making any changes.
B5: 📋 WORKBOOK OVERVIEW
B6: Three tabs work together — each has a different purpose
B7: Tab 1 — Action Tracker | C7: The main working list. 72 action items, one per row. Every conference task from booking flights to post-show Salesforce entry. Owners, due dates, status dropdowns, actual cost tracking, and reference numbers (ACT-001 to ACT-072). This is what the team updates week to week.
B8: Tab 2 — Dashboard | C8: Auto-updates as you change statuses in the Action Tracker. Shows completion % by owner and by month. No manual entry needed — just change statuses in Tab 1 and this refreshes automatically.
B9: Tab 3 — Year Calendar | C9: One row per conference — the full 2026 calendar view. Dates, locations, attendees, booth status, estimated cost, and the APPROVAL column. This is where Jon's approval decisions are recorded and where budget totals by approval status are calculated.
B10: Companion HTML Portal | C10: The HTML Conference Action Plan file (open in Chrome) is the visual review layer. Use it to browse conferences, approve/reject in the browser, and export a summary. The Download buttons in the HTML deliver this Excel and the Budget Model directly.
B13: ✅ APPROVAL WORKFLOW — Step by Step
B14: Jon reviews conferences in the HTML portal → decisions recorded here in Year Calendar tab → actions activate in Action Tracker
A15: 1 | B15: Open the HTML Conference Action Plan in Chrome | C15: File: BU_Services_Conference_Action_Plan.html. Open locally in Chrome or from SharePoint. The Approval Summary panel is at the very top below the header — it shows 0 approved until you start deciding.
A16: 2 | B16: Review each conference card | C16: Scroll to Section 03 — Conference Action Cards. Each card shows the conference details, strategic score, estimated cost, initiative alignment, and full action checklist. Filter by priority using the buttons at the top of the section.
A17: 3 | B17: Click Approve / Hold / Reject on each card | C17: Each card has a decision bar at the bottom. ✓ Approve = green border. ⏸ Hold = amber. ✗ Reject = card dims to 50% opacity. Add an optional note in the text field (e.g. 'Budget too high — reduce headcount' or 'Confirm waitlist first'). Decisions save automatically to browser localStorage — they persist if you close and reopen the file.
A18: 4 | B18: Review the Approval Summary panel | C18: The panel at the top of the HTML updates in real time: count of Approved / On Hold / Rejected / Pending, and four budget totals showing how much spend is committed, on hold, cut, or undecided.
A19: 5 | B19: Export Approvals | C19: Click the '📤 Export Approvals' button in the summary panel. A modal appears with a formatted text summary of all decisions. Click 'Copy to Clipboard'. This gives you the full list to share with Shanny and the commercial team.
A20: 6 | B20: Update this Excel — Year Calendar tab → Column M | C20: Open the Year Calendar tab. Find each conference. Change the dropdown in Column M (Approval Decision) to match your HTML decisions: Approved / On Hold / Rejected / Pending. The cell turns green/amber/red automatically. Add any notes in Column N. The four budget summary rows at the bottom update instantly.
A21: 7 | B21: Action Tracker auto-reflects the decisions | C21: The Action Tracker tab has a Column O (Conference Approval) which VLOOKUP pulls from the Year Calendar. Any conference marked Rejected will show 'Rejected' in red next to every related action item — Shanny and the team immediately know which logistics to cancel or not book.
B24: 📝 ACTION TRACKER — Column Guide
B25: Tab 1 · 72 rows · one action per row
B26: A — Month | C26: Which calendar month this action belongs to (Jan, Feb, Mar... or 'Ongoing' for standing items). Used by Dashboard to calculate monthly completion rates.
B27: B — Conference | C27: Conference name. Links to Year Calendar via VLOOKUP for the approval status. 'ALL SHOWS' = applies to every conference (standing rules).
B28: C — Priority | C28: HIGH / MED-H / MED / LOW — matches the conference priority rating from the strategic scoring model.
B29: D — Initiative | C29: Which of the 5 BU Services initiatives this action serves: Mining NDT · Pipeline DA · Powerline · Nuclear/OPG · 3X Composite · All Initiatives.
B30: E — Owner | C30: Person responsible for completing this action. Shanny Tremblay = all logistics. Commercial leads = account prep and Salesforce. Jon = strategic decisions.
B31: F — Category | C31: Logistics (travel, hotels, freight, booth) · Commercial (account prep, Salesforce, messaging) · Admin (budget review, standing rules).
B32: G — Action Item | C32: The specific task. Written as a clear instruction — not a vague goal. Each action has a single owner and a single deliverable.
B33: H — Due Date | C33: Target completion date. Format: YYYY-MM-DD for sortable dates, or relative ('After each show', 'Monthly', 'Quarterly'). Sort this column to see what's coming up.
B34: I — Status | C34: DROPDOWN — change this to track progress. Not Started (default/red) · In Progress (amber) · Complete (green) · Blocked (purple) · N/A (grey). The Dashboard tab reads this column for all completion metrics.
B35: J — Actual Cost | C35: Enter real invoice amounts here as they come in (blue = input cell). Used by the running total at the bottom and by the quarterly budget vs actual review.
B36: K — Done ☐ | C36: Manual checkbox column — tick ☑ when complete as a quick visual scan. Not formula-driven, just a convenience column for Shanny's weekly review.
B37: L — Completed Date | C37: Enter the date when status is changed to Complete. Helps track whether actions were done on time vs late.
... B40: O — Conf. Approval | C40: Auto-populated via VLOOKUP from Year Calendar Col M. Shows the approval status of the parent conference — turns green/amber/red. If a conference is Rejected, all its action items show 'Rejected' here so Shanny knows to cancel bookings.
B43: 🔴🟡🟢 STATUS DROPDOWN GUIDE
B44: Not Started | C44: Default state for all actions. Red text on red background. No work has begun.
B45: In Progress | C45: Work has started but is not complete. Amber. Use this when flights are being searched, a hotel is being checked, or a prep deck is being drafted.
B46: Complete | C46: Action fully done. Green. For logistics: booking confirmed + confirmation email received. For commercial: leads in Salesforce + tagged correctly.
B47: Blocked | C47: Cannot proceed — waiting on something external (e.g. waitlist response, Jon decision, budget approval). Purple. Add a note in Col M explaining what is blocking it.
B48: N/A | C48: Action does not apply — e.g. a booth-shipping action for a walkin-only conference. Grey. Better than deleting the row as it preserves the audit trail.
B51: 👤 WHO DOES WHAT — Owner Quick Reference
B52: Shanny Tremblay | C52: Conference Logistics | D52: All flight bookings, hotel reservations, badge registration, booth coordination, freight shipping. Highest action count. Start Jan–Mar bookings immediately.
...

Sheet Action Tracker
A3: Read this before using the tracker. Three roles. Each has a specific job. None overlap.
A5: 📋 SHANNY TREMBLAY — Conference Logistics | F5: ✅ JON EUSTACE — Conference Approvals & SF Outcomes | K5: 💰 JEREMY IRWIN — Budget vs Actual Review
A6: Logistics Coordinator — BU Services (Nucleom/Nortech) ONLY | F6: CEO North America — Strategic decisions + commercial outcomes | K6: Director of Finance, EIG North America — Financial oversight
A7: ✔ After each BU Services conference: open this file on SharePoint | F7: ✔ Review Conference Action Plan (HTML) → Approve / Hold / Reject each show | K7: ✔ Quarterly budget vs actual review: Apr 15 · Jul 15 · Oct 15 · Jan 15
A8: ✔ Year Calendar tab → find conference row → enter total actual cost in Column S “Total Actual (CAD)” | F8: ✔ After each conference: run SF report 'Conference Leads 2026' | K8: ✔ Reviews Col J (cost breakdown) vs Col K (budget estimate) per conference
A9: ✔ Action Tracker tab → enter actual costs by category (Col J) for detail | F9: ✔ Enter leads + opps counts via Teams Adaptive Card (sent automatically) | K9: ✔ Flags any show exceeding budget by >15% — brief explanation required
A10: ✔ NOT responsible for Ekoscan BU shows (PPIM, NDTMA, AMPP, COFREND, API EIG) | F10: ✔ This feeds Cost per Lead + Cost per Opp KPIs in the Command Centre | K10: ✔ Reviews Salesforce outcomes (leads, opps) alongside cost data
A11: ⚠ ALL ATTENDEES — 48-HOUR SALESFORCE RULE: Enter all leads in Salesforce within 48 hours of returning. Tag BU_Initiative__c on every opportunity. No exceptions — the Sunday PA flow reads this data.
A13: Month | B13: Conference | C13: Priority | D13: Initiative | E13: Owner | F13: Category | G13: Action Item | H13: Due Date | I13: Status | J13: Actual Cost (CAD) | K13: Done ? | L13: Completed Date | M13: Notes / Updates | N13: Ref # | O13: Conference Approval | P13: Logistics Owner (BU)
A14: Jan | B14: PPIM 2026 | C14: HIGH | D14: Pipeline DA | E14: Rick Carlton | F14: Logistics | G14: Confirm booth #113 details and freight shipping address with organizer | H14: 2025-12-15 | I14: Not Started | K14: ☐ | M14: Already booked | N14: ACT-001 | O14: =IFERROR(VLOOKUP(B6,'Year Calendar'!C:M,11,0),"Pending") -> Pending | P14: Ekoscan BU
A15: Jan | B15: PPIM 2026 | C15: HIGH | D15: Pipeline DA | E15: Ekoscan BU Logistics | F15: Logistics | G15: Book flights YQB→Houston (IAH) for Jeff, Anthony, Aaron | H15: 2025-12-01 | I15: Not Started | K15: ☐ | M15: Ekoscan BU manages logistics — coordinate only · Return ~$820/person CAD | N15: ACT-002 | O15: =IFERROR(VLOOKUP(B7,'Year Calendar'!C:M,11,0),"Pending") -> Pending | P15: Ekoscan BU
A16: Jan | B16: PPIM 2026 | C16: HIGH | D16: Pipeline DA | E16: Ekoscan BU Logistics | F16: Logistics | G16: Book hotel — Hilton Americas or nearby for 5 nights | H16: 2025-12-01 | I16: Not Started | K16: ☐ | M16: Ekoscan BU manages logistics — coordinate only · ~$295/night | N16: ACT-003 | O16: =IFERROR(VLOOKUP(B8,'Year Calendar'!C:M,11,0),"Pending") -> Pending | P16: Ekoscan BU
A17: Jan | B17: PPIM 2026 | C17: HIGH | D17: Pipeline DA | E17: Rick Carlton | F17: Commercial | G17: Prepare Pipeline DA talking points and target account list for Houston | H17: 2025-12-20 | I17: Not Started | K17: ☐ | M17: Align with Vinoth on messaging | N17: ACT-004 | O17: =IFERROR(VLOOKUP(B9,'Year Calendar'!C:M,11,0),"Pending") -> Pending | P17: Ekoscan BU
A18: Jan | B18: PPIM 2026 | C18: HIGH | D18: Pipeline DA | E18: Ekoscan BU Logistics | F18: Logistics | G18: Ship booth display and materials to George R. Brown Convention Center | H18: 2026-01-10 | I18: Not Started | K18: ☐ | M18: Ekoscan BU manages logistics — coordinate only · Allow 5 business days lead | N18: ACT-005 | O18: =IFERROR(VLOOKUP(B10,'Year Calendar'!C:M,11,0),"Pending") -> Pending | P18: Ekoscan BU
A19: Jan | B19: PPIM 2026 | C19: HIGH | D19: Pipeline DA | E19: Rick Carlton | F19: Commercial | G19: Schedule post-show debrief and enter leads into Salesforce within 48h of return | H19: 2026-01-25 | I19: Not Started | K19: ☐ | M19: Tag all opps with BU_Initiative__c = Pipeline | N19: ACT-006 | O19: =IFERROR(VLOOKUP(B11,'Year Calendar'!C:M,11,0),"Pending") -> Pending | P19: Ekoscan BU
A20: Feb | B20: NDTMA 2026 | C20: HIGH | D20: Mining NDT | E20: Vinoth Tharma | F20: Commercial | G20: Prepare TFM/PCI presentation — confirm with organizer abstract deadline | H20: 2026-01-15 | I20: Not Started | K20: ☐ | M20: Speaker slot confirmed | N20: ACT-007 | O20: =IFERROR(VLOOKUP(B12,'Year Calendar'!C:M,11,0),"Pending") -> Pending | P20: Ekoscan BU
A21: Feb | B21: NDTMA 2026 | C21: HIGH | D21: Mining NDT | E21: Ekoscan BU Logistics | F21: Logistics | G21: Book flights YQB→Las Vegas for Dillon, Jeff, Fred, Guillaume, Anthony | H21: 2025-12-15 | I21: Not Started | K21: ☐ | M21: Ekoscan BU manages logistics — coordinate only · Return ~$750/person CAD | N21: ACT-008 | O21: =IFERROR(VLOOKUP(B13,'Year Calendar'!C:M,11,0),"Pending") -> Approval Decision | P21: Ekoscan BU
A22: Feb | B22: NDTMA 2026 | C22: HIGH | D22: Mining NDT | E22: Ekoscan BU Logistics | F22: Logistics | G22: Book hotel — Golden Nugget, 4 nights | H22: 2025-12-15 | I22: Not Started | K22: ☐ | M22: Ekoscan BU manages logistics — coordinate only · ~$295/night | N22: ACT-009 | O22: =IFERROR(VLOOKUP(B14,'Year Calendar'!C:M,11,0),"Pending") -> Pending | P22: Ekoscan BU
A23: Feb | B23: NDTMA 2026 | C23: HIGH | D23: Mining NDT | E23: Vinoth Tharma | F23: Commercial | G23: Identify top 10 Mining NDT target accounts attending — pre-book meetings | H23: 2026-01-30 | I23: Not Started | K23: ☐ | M23: Cross-ref with Salesforce account list | N23: ACT-010 | O23: =IFERROR(VLOOKUP(B15,'Year Calendar'!C:M,11,0),"Pending") -> Pending | P23: Ekoscan BU
A24: Feb | B24: NDTMA 2026 | C24: HIGH | D24: Mining NDT | E24: Max Aggrey | F24: Commercial | G24: Prepare 3X Composite repair cross-sell kit for NDTMA — embed in every finding conversation | H24: 2026-01-30 | I24: Not Started | K24: ☐ | M24: 3X = embed at every AMBER/RED finding | N24: ACT-011 | O24: =IFERROR(VLOOKUP(B16,'Year Calendar'!C:M,11,0),"Pending") -> Pending | P24: Ekoscan BU
A25: Feb | B25: NDTMA 2026 | C25: HIGH | D25: Mining NDT | E25: Rick Carlton | F25: Commercial | G25: Post-show: enter all leads in Salesforce, tag Pipeline DA where applicable | H25: 2026-02-22 | I25: Not Started | K25: ☐ | M25: 48h turnaround rule | N25: ACT-012 | O25: =IFERROR(VLOOKUP(B17,'Year Calendar'!C:M,11,0),"Pending") -> Pending | P25: Ekoscan BU
... A44: May | B44: T&D Conference | C44: MED | D44: Powerline | E44: Mathieu Beauchesne | F44: Commercial | G44: T&D prep: Powerline initiative deck + Hydro One/AltaLink/ATCO target list | H44: 2026-04-15 | I44: Not Started | K44: ☐ | M44: $10.2M initiative — primary dedicated show | N44: ACT-031 | O44: =IFERROR(VLOOKUP(B36,'Year Calendar'!C:M,11,0),"Pending") -> Pending | P44: BU Services
A45: May | B45: T&D Conference | C45: MED | D45: Powerline | E45: Mathieu Beauchesne | F45: Commercial | G45: Post-show: enter Powerline prospects in Salesforce — tag BU_Initiative__c = Powerline | H45: 2026-05-10 | I45: Not Started | K45: ☐ | N45: ACT-032 | O45: =IFERROR(VLOOKUP(B37,'Year Calendar'!C:M,11,0),"Pending") -> Pending | P45: BU Services
A46: May | B46: CIM Vancouver | C46: MED | D46: Mining NDT | E46: Vinoth Tharma | F46: Logistics | G46: CIM Vancouver — register walkin badges for Vinoth + Max | H46: 2026-04-01 | I46: Not Started | K46: ☐ | M46: Walkin only — technical paper TBC | N46: ACT-033 | O46: =IFERROR(VLOOKUP(B38,'Year Calendar'!C:M,11,0),"Pending") -> Pending | P46: BU Services
A47: May | B47: CIM Vancouver | C47: MED | D47: Mining NDT | E47: Vinoth Tharma | F47: Commercial | G47: Submit technical paper abstract if deadline not passed — confirm with organizer | H47: 2026-03-01 | I47: Not Started | K47: ☐ | M47: Speaker slot = credibility boost | N47: ACT-034 | O47: =IFERROR(VLOOKUP(B39,'Year Calendar'!C:M,11,0),"Pending") -> Pending | P47: BU Services
A48: May | B48: CIM Vancouver | C48: MED | D48: Mining NDT | E48: Max Aggrey | F48: Commercial | G48: BC mining target list: Teck, Copper Mountain, Highland Valley — pre-book meetings | H48: 2026-04-15 | I48: Not Started | K48: ☐ | M48: West coast mining focus | N48: ACT-035 | O48: =IFERROR(VLOOKUP(B40,'Year Calendar'!C:M,11,0),"Pending") -> Pending | P48: BU Services
A49: Jun | B49: ECNDT Verona | C49: HIGH | D49: All Initiatives | E49: Jon Eustace | F49: Commercial | G49: ECNDT prep: coordinate EIG + Nucleom joint messaging and booth strategy | H49: 2026-05-01 | I49: Not Started | K49: ☐ | M49: Largest EIG NDT presence of the year | N49: ACT-036 | O49: =IFERROR(VLOOKUP(B41,'Year Calendar'!C:M,11,0),"Pending") -> Pending | P49: Joint
A50: Jun | B50: ECNDT Verona | C50: HIGH | D50: All Initiatives | E50: Shanny Tremblay | F50: Logistics | G50: Book flights YQB→Milan/Verona for Xavier, Guillaume, Lucy, Hervé, Fabian | H50: 2026-03-01 | I50: Not Started | K50: ☐ | M50: Return ~$1,900 CAD each — book early | N50: ACT-037 | O50: =IFERROR(VLOOKUP(B42,'Year Calendar'!C:M,11,0),"Pending") -> Pending | P50: Joint
A51: Jun | B51: ECNDT Verona | C51: HIGH | D51: All Initiatives | E51: Shanny Tremblay | F51: Logistics | G51: Book hotel Verona — 6 nights × 5 people (~$310/night) | H51: 2026-03-01 | I51: Not Started | K51: ☐ | M51: Book early — Verona fills up for ECNDT | N51: ACT-038 | O51: =IFERROR(VLOOKUP(B43,'Year Calendar'!C:M,11,0),"Pending") -> Pending | P51: Joint
A52: Jun | B52: ECNDT Verona | C52: HIGH | D52: All Initiatives | E52: Shanny Tremblay | F52: Logistics | G52: Ship booth materials (international freight) — allow 3 weeks lead time | H52: 2026-05-25 | I52: Not Started | K52: ☐ | M52: Consider Pelican carry-on for key displays | N52: ACT-039 | O52: =IFERROR(VLOOKUP(B44,'Year Calendar'!C:M,11,0),"Pending") -> Pending | P52: Joint
A53: Jun | B53: ECNDT Verona | C53: HIGH | D53: Mining NDT | E53: Vinoth Tharma | F53: Commercial | G53: Pre-schedule meetings with European mining + nuclear operators at ECNDT | H53: 2026-05-15 | I53: Not Started | K53: ☐ | M53: Global account development | N53: ACT-040 | O53: =IFERROR(VLOOKUP(B45,'Year Calendar'!C:M,11,0),"Pending") -> Pending | P53: Joint
A54: Jun | B54: Canadian Mining Expo | C54: MED | D54: Mining NDT | E54: Jon Eustace | F54: Commercial | G54: PURSUE WAITLIST actively — contact organizer re: speaker slot availability | H54: 2026-01-15 | I54: Not Started | K54: ☐ | M54: Currently on waitlist — speaker = priority entry | N54: ACT-041 | O54: =IFERROR(VLOOKUP(B46,'Year Calendar'!C:M,11,0),"Pending") -> Pending | P54: BU Services
A55: Jun | B55: Canadian Mining Expo | C55: MED | D55: Mining NDT | E55: Shanny Tremblay | F55: Logistics | G55: Book flights YQB→Timmins for Keith + speaker (once confirmed off waitlist) | H55: 2026-04-01 | I55: Not Started | K55: ☐ | M55: Regional connection via Toronto ~$580 CAD | N55: ACT-042 | O55: =IFERROR(VLOOKUP(B47,'Year Calendar'!C:M,11,0),"Pending") -> Pending | P55: BU Services
A56: Jun | B56: Canadian Mining Expo | C56: MED | D56: Mining NDT | E56: Vinoth Tharma | F56: Commercial | G56: Timmins target accounts: Vale Timmins, Kinross, Pan American Silver | H56: 2026-05-15 | I56: Not Started | K56: ☐ | M56: Northern Ontario mining corridor | N56: ACT-043 | O56: =IFERROR(VLOOKUP(B48,'Year Calendar'!C:M,11,0),"Pending") -> Pending | P56: BU Services
A57: Jul | B57: API Inspection Summit | C57: HIGH | D57: Pipeline DA | E57: Jon Eustace | F57: Commercial | G57: COORDINATE with Ekoscan BU — combine booth, split cost, unified message | H57: 2026-05-01 | I57: Not Started | K57: ☐ | M57: Both teams attending separately — consolidate saves ~$12K | N57: ACT-044 | O57: =IFERROR(VLOOKUP(B49,'Year Calendar'!C:M,11,0),"Pending") -> Pending | P57: BU Services
... A60: Jul | B60: API Inspection Summit | C60: HIGH | D60: Pipeline DA | E60: Rick Carlton | F60: Commercial | G60: API show prep: Pipeline DA + 3X + Base Business target list — US operators | H60: 2026-06-20 | I60: Not Started | K60: ☐ | M60: Major US pipeline operators in attendance | N60: ACT-047 | O60: =IFERROR(VLOOKUP(B52,'Year Calendar'!C:M,11,0),"Pending") -> Pending | P60: BU Services
A61: Jul | B61: API Inspection Summit | C61: HIGH | D61: Pipeline DA | E61: Rick Carlton | F61: Commercial | G61: Post-show Salesforce entry — all Pipeline DA + 3X opps within 48h | H61: 2026-07-27 | I61: Not Started | K61: ☐ | N61: ACT-048 | O61: =IFERROR(VLOOKUP(B53,'Year Calendar'!C:M,11,0),"Pending") -> Pending | P61: BU Services
A62: Aug | B62: Cigre Paris | C62: MED | D62: Powerline | E62: Mathieu Beauchesne | F62: Logistics | G62: Book flights YQB→Paris CDG for Math +1 — book 6+ months ahead for best rate | H62: 2026-02-15 | I62: Not Started | K62: ☐ | M62: Return ~$1,850 CAD — book early | N62: ACT-049 | O62: =IFERROR(VLOOKUP(B54,'Year Calendar'!C:M,11,0),"Pending") -> Pending | P62: BU Services
A63: Aug | B63: Cigre Paris | C63: MED | D63: Powerline | E63: Shanny Tremblay | F63: Logistics | G63: Book hotel Paris — 7 nights × 2 people, near Palais des Congrès | H63: 2026-02-15 | I63: Not Started | K63: ☐ | M63: ~$310/night | N63: ACT-050 | O63: =IFERROR(VLOOKUP(B55,'Year Calendar'!C:M,11,0),"Pending") -> Pending | P63: BU Services
A64: Aug | B64: Cigre Paris | C64: MED | D64: Powerline | E64: Mathieu Beauchesne | F64: Commercial | G64: Cigre prep: T&D / Powerline initiative follow-up from T&D Chicago contacts | H64: 2026-07-30 | I64: Not Started | K64: ☐ | M64: Global T&D relationships — EIG alignment | N64: ACT-051 | O64: =IFERROR(VLOOKUP(B56,'Year Calendar'!C:M,11,0),"Pending") -> Pending | P64: BU Services
...

Sheet Dashboard
A1: CONFERENCE ACTION PLAN — PROGRESS DASHBOARD 2026
A3: STATUS SUMMARY (auto-updates as you mark items complete in Action Tracker)
A4: Total Actions | B4: Not Started | C4: In Progress | D4: Complete | E4: Blocked
A5: =COUNTA('Action Tracker'!G6:G77) -> 64 | B5: =COUNTIF('Action Tracker'!I6:I77,"Not Started") -> 63 | C5: =COUNTIF('Action Tracker'!I6:I77,"In Progress") -> 0 | D5: =COUNTIF('Action Tracker'!I6:I77,"Complete") -> 0 | E5: =COUNTIF('Action Tracker'!I6:I77,"Blocked") -> 0
A6: =TEXT(COUNTIF('Action Tracker'!I6:I77,"Complete")/COUNTA('Action Tracker'!G6:G77)*100,"0.0")&"% of actions complete" -> 0.0% of actions complete
A8: ACTIONS BY OWNER
A9: Owner | B9: Total | C9: Not Started | D9: In Progress | E9: Complete | F9: Blocked | G9: % Done
A10: Jon Eustace | B10: =COUNTIF('Action Tracker'!E6:E77,"Jon Eustace") -> 6 | C10: =COUNTIFS('Action Tracker'!E6:E77,"Jon Eustace",'Action Tracker'!I6:I77,"Not Started") -> 6 | D10: =COUNTIFS('Action Tracker'!E6:E77,"Jon Eustace",'Action Tracker'!I6:I77,"In Progress") -> 0 | E10: =COUNTIFS('Action Tracker'!E6:E77,"Jon Eustace",'Action Tracker'!I6:I77,"Complete") -> 0 | F10: =COUNTIFS('Action Tracker'!E6:E77,"Jon Eustace",'Action Tracker'!I6:I77,"Blocked") -> 0 | G10: =IFERROR(COUNTIFS('Action Tracker'!E6:E77,"Jon Eustace",'Action Tracker'!I6:I77,"Complete")/COUNTIF('Action Tracker'!E6:E77,"Jon Eustace"),0) -> 0
A11: Olivier Marcotte | B11: =COUNTIF('Action Tracker'!E6:E77,"Olivier Marcotte") -> 2 | C11: =COUNTIFS('Action Tracker'!E6:E77,"Olivier Marcotte",'Action Tracker'!I6:I77,"Not Started") -> 2 | D11: =COUNTIFS('Action Tracker'!E6:E77,"Olivier Marcotte",'Action Tracker'!I6:I77,"In Progress") -> 0 | E11: =COUNTIFS('Action Tracker'!E6:E77,"Olivier Marcotte",'Action Tracker'!I6:I77,"Complete") -> 0 | F11: =COUNTIFS('Action Tracker'!E6:E77,"Olivier Marcotte",'Action Tracker'!I6:I77,"Blocked") -> 0 | G11: =IFERROR(COUNTIFS('Action Tracker'!E6:E77,"Olivier Marcotte",'Action Tracker'!I6:I77,"Complete")/COUNTIF('Action Tracker'!E6:E77,"Olivier Marcotte"),0) -> 0
A12: Vinoth Tharma | B12: =COUNTIF('Action Tracker'!E6:E77,"Vinoth Tharma") -> 11 | C12: =COUNTIFS('Action Tracker'!E6:E77,"Vinoth Tharma",'Action Tracker'!I6:I77,"Not Started") -> 11 | D12: =COUNTIFS('Action Tracker'!E6:E77,"Vinoth Tharma",'Action Tracker'!I6:I77,"In Progress") -> 0 | E12: =COUNTIFS('Action Tracker'!E6:E77,"Vinoth Tharma",'Action Tracker'!I6:I77,"Complete") -> 0 | F12: =COUNTIFS('Action Tracker'!E6:E77,"Vinoth Tharma",'Action Tracker'!I6:I77,"Blocked") -> 0 | G12: =IFERROR(COUNTIFS('Action Tracker'!E6:E77,"Vinoth Tharma",'Action Tracker'!I6:I77,"Complete")/COUNTIF('Action Tracker'!E6:E77,"Vinoth Tharma"),0) -> 0
A13: Max Aggrey | B13: =COUNTIF('Action Tracker'!E6:E77,"Max Aggrey") -> 4 | C13: =COUNTIFS('Action Tracker'!E6:E77,"Max Aggrey",'Action Tracker'!I6:I77,"Not Started") -> 4 | D13: =COUNTIFS('Action Tracker'!E6:E77,"Max Aggrey",'Action Tracker'!I6:I77,"In Progress") -> 0 | E13: =COUNTIFS('Action Tracker'!E6:E77,"Max Aggrey",'Action Tracker'!I6:I77,"Complete") -> 0 | F13: =COUNTIFS('Action Tracker'!E6:E77,"Max Aggrey",'Action Tracker'!I6:I77,"Blocked") -> 0 | G13: =IFERROR(COUNTIFS('Action Tracker'!E6:E77,"Max Aggrey",'Action Tracker'!I6:I77,"Complete")/COUNTIF('Action Tracker'!E6:E77,"Max Aggrey"),0) -> 0
A14: Rick Carlton | B14: =COUNTIF('Action Tracker'!E6:E77,"Rick Carlton") -> 11 | C14: =COUNTIFS('Action Tracker'!E6:E77,"Rick Carlton",'Action Tracker'!I6:I77,"Not Started") -> 11 | D14: =COUNTIFS('Action Tracker'!E6:E77,"Rick Carlton",'Action Tracker'!I6:I77,"In Progress") -> 0 | E14: =COUNTIFS('Action Tracker'!E6:E77,"Rick Carlton",'Action Tracker'!I6:I77,"Complete") -> 0 | F14: =COUNTIFS('Action Tracker'!E6:E77,"Rick Carlton",'Action Tracker'!I6:I77,"Blocked") -> 0 | G14: =IFERROR(COUNTIFS('Action Tracker'!E6:E77,"Rick Carlton",'Action Tracker'!I6:I77,"Complete")/COUNTIF('Action Tracker'!E6:E77,"Rick Carlton"),0) -> 0
A15: Mathieu Beauchesne | B15: =COUNTIF('Action Tracker'!E6:E77,"Mathieu Beauchesne") -> 4 | C15: =COUNTIFS('Action Tracker'!E6:E77,"Mathieu Beauchesne",'Action Tracker'!I6:I77,"Not Started") -> 4 | D15: =COUNTIFS('Action Tracker'!E6:E77,"Mathieu Beauchesne",'Action Tracker'!I6:I77,"In Progress") -> 0 | E15: =COUNTIFS('Action Tracker'!E6:E77,"Mathieu Beauchesne",'Action Tracker'!I6:I77,"Complete") -> 0 | F15: =COUNTIFS('Action Tracker'!E6:E77,"Mathieu Beauchesne",'Action Tracker'!I6:I77,"Blocked") -> 0 | G15: =IFERROR(COUNTIFS('Action Tracker'!E6:E77,"Mathieu Beauchesne",'Action Tracker'!I6:I77,"Complete")/COUNTIF('Action Tracker'!E6:E77,"Mathieu Beauchesne"),0) -> 0
A16: Éric Carmichael | B16: =COUNTIF('Action Tracker'!E6:E77,"Éric Carmichael") -> 0 | C16: =COUNTIFS('Action Tracker'!E6:E77,"Éric Carmichael",'Action Tracker'!I6:I77,"Not Started") -> 0 | D16: =COUNTIFS('Action Tracker'!E6:E77,"Éric Carmichael",'Action Tracker'!I6:I77,"In Progress") -> 0 | E16: =COUNTIFS('Action Tracker'!E6:E77,"Éric Carmichael",'Action Tracker'!I6:I77,"Complete") -> 0 | F16: =COUNTIFS('Action Tracker'!E6:E77,"Éric Carmichael",'Action Tracker'!I6:I77,"Blocked") -> 0 | G16: =IFERROR(COUNTIFS('Action Tracker'!E6:E77,"Éric Carmichael",'Action Tracker'!I6:I77,"Complete")/COUNTIF('Action Tracker'!E6:E77,"Éric Carmichael"),0) -> 0
A17: Alex Cyr | B17: =COUNTIF('Action Tracker'!E6:E77,"Alex Cyr") -> 1 | C17: =COUNTIFS('Action Tracker'!E6:E77,"Alex Cyr",'Action Tracker'!I6:I77,"Not Started") -> 1 | D17: =COUNTIFS('Action Tracker'!E6:E77,"Alex Cyr",'Action Tracker'!I6:I77,"In Progress") -> 0 | E17: =COUNTIFS('Action Tracker'!E6:E77,"Alex Cyr",'Action Tracker'!I6:I77,"Complete") -> 0 | F17: =COUNTIFS('Action Tracker'!E6:E77,"Alex Cyr",'Action Tracker'!I6:I77,"Blocked") -> 0 | G17: =IFERROR(COUNTIFS('Action Tracker'!E6:E77,"Alex Cyr",'Action Tracker'!I6:I77,"Complete")/COUNTIF('Action Tracker'!E6:E77,"Alex Cyr"),0) -> 0
A18: Shanny Tremblay | B18: =COUNTIF('Action Tracker'!E6:E85,"Shanny Tremblay") -> 17 | C18: =COUNTIFS('Action Tracker'!E6:E85,"Shanny Tremblay",'Action Tracker'!I6:I85,"Not Started") -> 17 | D18: =COUNTIFS('Action Tracker'!E6:E85,"Shanny Tremblay",'Action Tracker'!I6:I85,"In Progress") -> 0 | E18: =COUNTIFS('Action Tracker'!E6:E85,"Shanny Tremblay",'Action Tracker'!I6:I85,"Complete") -> 0 | F18: =COUNTIFS('Action Tracker'!E6:E85,"Shanny Tremblay",'Action Tracker'!I6:I85,"Blocked") -> 0 | G18: BU Services logistics (Nucleom/Nortech staff only). Shanny is NOT responsible for Ekoscan BU shows.
A19: All Attendees | B19: =COUNTIF('Action Tracker'!E6:E77,"All Attendees") -> 0 | C19: =COUNTIFS('Action Tracker'!E6:E77,"All Attendees",'Action Tracker'!I6:I77,"Not Started") -> 0 | D19: =COUNTIFS('Action Tracker'!E6:E77,"All Attendees",'Action Tracker'!I6:I77,"In Progress") -> 0 | E19: =COUNTIFS('Action Tracker'!E6:E77,"All Attendees",'Action Tracker'!I6:I77,"Complete") -> 0 | F19: =COUNTIFS('Action Tracker'!E6:E77,"All Attendees",'Action Tracker'!I6:I77,"Blocked") -> 0 | G19: =IFERROR(COUNTIFS('Action Tracker'!E6:E77,"All Attendees",'Action Tracker'!I6:I77,"Complete")/COUNTIF('Action Tracker'!E6:E77,"All Attendees"),0) -> 0
A22: ACTIONS BY MONTH
A23: Month | B23: Total Actions | C23: Complete | D23: % Done | E23: Upcoming Conferences
A24: Jan | B24: =COUNTIF('Action Tracker'!A6:A77,"Jan") -> 6 | C24: =COUNTIFS('Action Tracker'!A6:A77,"Jan",'Action Tracker'!I6:I77,"Complete") -> 0 | D24: =IFERROR(COUNTIFS('Action Tracker'!A6:A77,"Jan",'Action Tracker'!I6:I77,"Complete")/COUNTIF('Action Tracker'!A6:A77,"Jan"),0) -> 0 | E24: PPIM 2026
A25: Feb | B25: =COUNTIF('Action Tracker'!A6:A77,"Feb") -> 6 | C25: =COUNTIFS('Action Tracker'!A6:A77,"Feb",'Action Tracker'!I6:I77,"Complete") -> 0 | D25: =IFERROR(COUNTIFS('Action Tracker'!A6:A77,"Feb",'Action Tracker'!I6:I77,"Complete")/COUNTIF('Action Tracker'!A6:A77,"Feb"),0) -> 0 | E25: NDTMA 2026
A26: Mar | B26: =COUNTIF('Action Tracker'!A6:A77,"Mar") -> 10 | C26: =COUNTIFS('Action Tracker'!A6:A77,"Mar",'Action Tracker'!I6:I77,"Complete") -> 0 | D26: =IFERROR(COUNTIFS('Action Tracker'!A6:A77,"Mar",'Action Tracker'!I6:I77,"Complete")/COUNTIF('Action Tracker'!A6:A77,"Mar"),0) -> 0 | E26: IPEIA · AMPP
A27: Apr | B27: =COUNTIF('Action Tracker'!A6:A77,"Apr") -> 7 | C27: =COUNTIFS('Action Tracker'!A6:A77,"Apr",'Action Tracker'!I6:I77,"Complete") -> 0 | D27: =IFERROR(COUNTIFS('Action Tracker'!A6:A77,"Apr",'Action Tracker'!I6:I77,"Complete")/COUNTIF('Action Tracker'!A6:A77,"Apr"),0) -> 0 | E27: CNA · Smart Energy Halifax
A28: May | B28: =COUNTIF('Action Tracker'!A6:A77,"May") -> 6 | C28: =COUNTIFS('Action Tracker'!A6:A77,"May",'Action Tracker'!I6:I77,"Complete") -> 0 | D28: =IFERROR(COUNTIFS('Action Tracker'!A6:A77,"May",'Action Tracker'!I6:I77,"Complete")/COUNTIF('Action Tracker'!A6:A77,"May"),0) -> 0 | E28: T&D · CIM Vancouver
A29: Jun | B29: =COUNTIF('Action Tracker'!A6:A77,"Jun") -> 8 | C29: =COUNTIFS('Action Tracker'!A6:A77,"Jun",'Action Tracker'!I6:I77,"Complete") -> 0 | D29: =IFERROR(COUNTIFS('Action Tracker'!A6:A77,"Jun",'Action Tracker'!I6:I77,"Complete")/COUNTIF('Action Tracker'!A6:A77,"Jun"),0) -> 0 | E29: ECNDT Verona · Canadian Mining Expo
A30: Jul | B30: =COUNTIF('Action Tracker'!A6:A77,"Jul") -> 5 | C30: =COUNTIFS('Action Tracker'!A6:A77,"Jul",'Action Tracker'!I6:I77,"Complete") -> 0 | D30: =IFERROR(COUNTIFS('Action Tracker'!A6:A77,"Jul",'Action Tracker'!I6:I77,"Complete")/COUNTIF('Action Tracker'!A6:A77,"Jul"),0) -> 0 | E30: API Inspection Summit
A31: Aug | B31: =COUNTIF('Action Tracker'!A6:A77,"Aug") -> 3 | C31: =COUNTIFS('Action Tracker'!A6:A77,"Aug",'Action Tracker'!I6:I77,"Complete") -> 0 | D31: =IFERROR(COUNTIFS('Action Tracker'!A6:A77,"Aug",'Action Tracker'!I6:I77,"Complete")/COUNTIF('Action Tracker'!A6:A77,"Aug"),0) -> 0 | E31: Cigre Paris
A32: Sep | B32: =COUNTIF('Action Tracker'!A6:A77,"Sep") -> 8 | C32: =COUNTIFS('Action Tracker'!A6:A77,"Sep",'Action Tracker'!I6:I77,"Complete") -> 0 | D32: =IFERROR(COUNTIFS('Action Tracker'!A6:A77,"Sep",'Action Tracker'!I6:I77,"Complete")/COUNTIF('Action Tracker'!A6:A77,"Sep"),0) -> 0 | E32: IPC Pipeline · IPCE · CEN CAN Expo
A33: Oct | B33: =COUNTIF('Action Tracker'!A6:A77,"Oct") -> 5 | C33: =COUNTIFS('Action Tracker'!A6:A77,"Oct",'Action Tracker'!I6:I77,"Complete") -> 0 | D33: =IFERROR(COUNTIFS('Action Tracker'!A6:A77,"Oct",'Action Tracker'!I6:I77,"Complete")/COUNTIF('Action Tracker'!A6:A77,"Oct"),0) -> 0 | E33: ASNT · API Storage Tank
A34: Ongoing | B34: =COUNTIF('Action Tracker'!A6:A77,"Ongoing") -> 0 | C34: =COUNTIFS('Action Tracker'!A6:A77,"Ongoing",'Action Tracker'!I6:I77,"Complete") -> 0 | D34: =IFERROR(COUNTIFS('Action Tracker'!A6:A77,"Ongoing",'Action Tracker'!I6:I77,"Complete")/COUNTIF('Action Tracker'!A6:A77,"Ongoing"),0) -> 0 | E34: Year-round standing items

Sheet Year Calendar
A1: BU SERVICES — 2026 CONFERENCE CALENDAR AT A GLANCE
A4: Month | B4: Priority | C4: Conference | D4: Dates | E4: Location | F4: Initiative | G4: # People | H4: BU Attendees | I4: Booth? | J4: Actions Due | K4: Est. Cost | L4: Status | M4: Approval Decision | N4: Jon's Notes / Rationale | O4: Budget Impact (CAD) | P4: Logistics Owner | Q4: Responsible Person | R4: Scope Note | S4: Total Actual (CAD)
A5: January | B5: HIGH | C5: PPIM 2026 | D5: Jan 19-22 | E5: Houston TX | F5: Pipeline DA | G5: 3 | H5: Jeff · Anthony · Aaron | I5: ✓ | J5: 6 | K5: 38000 | L5: Not Started | M5: Pending | O5: =IF(M5="Approved",K5,IF(M5="Rejected",-K5,IF(M5="On Hold",K5,0))) -> 0 | P5: Ekoscan BU | Q5: Ekoscan Logistics Team | R5: Ekoscan manages logistics — Shanny NOT responsible
A6: February | B6: HIGH | C6: NDTMA 2026 | D6: Feb 17-19 | E6: Las Vegas NV | F6: Mining NDT | G6: 5 | H6: Dillon · Jeff · Fred · Guillaume · Anthony | I6: ✓ | J6: 6 | K6: 42000 | L6: Not Started | M6: Pending | O6: =IF(M6="Approved",K6,IF(M6="Rejected",-K6,IF(M6="On Hold",K6,0))) -> 0 | P6: Ekoscan BU | Q6: Ekoscan Logistics Team | R6: Ekoscan manages logistics — Shanny NOT responsible
A7: March | B7: HIGH | C7: IPEIA 2026 | D7: Mar 10-12 | E7: Calgary AB | F7: All Initiatives | G7: 6 | H7: Max · Keith · Tim · Alex · Rick · Marcos | I7: ✓ | J7: 7 | K7: 55000 | L7: Not Started | M7: Pending | O7: =IF(M7="Approved",K7,IF(M7="Rejected",-K7,IF(M7="On Hold",K7,0))) -> 0 | P7: BU Services | Q7: Shanny Tremblay | R7: Shanny Tremblay handles all logistics for Nucleom/Nortech staff
B8: HIGH | C8: AMPP 2026 | D8: Mar 15-19 | E8: Houston TX | F8: Pipeline DA · 3X | G8: 2 | H8: Vincent Ribouleau | I8: ✓ | J8: 3 | K8: 28000 | L8: Not Started | M8: Pending | O8: =IF(M8="Approved",K8,IF(M8="Rejected",-K8,IF(M8="On Hold",K8,0))) -> 0 | P8: Ekoscan BU | Q8: Ekoscan Logistics Team | R8: Ekoscan manages logistics — Shanny NOT responsible
A9: April | B9: HIGH | C9: CNA 2026 | D9: Apr 28-30 | E9: Ottawa ON | F9: Nuclear/OPG | G9: 4 | H9: Oli · Jon · LP · Sha | I9: — | J9: 5 | K9: 22000 | L9: Not Started | M9: Pending | O9: =IF(M9="Approved",K9,IF(M9="Rejected",-K9,IF(M9="On Hold",K9,0))) -> 0 | P9: BU Services | Q9: Shanny Tremblay | R9: Shanny Tremblay handles all logistics for Nucleom/Nortech staff
B10: LOW | C10: Smart Energy Halifax | D10: Apr 14-15 | E10: Halifax NS | F10: Powerline | G10: 3 | H10: Alex · Eric · Vinoth | I10: — | J10: 2 | K10: 8000 | L10: Not Started | M10: Pending | O10: =IF(M10="Approved",K10,IF(M10="Rejected",-K10,IF(M10="On Hold",K10,0))) -> 0 | P10: BU Services | Q10: Shanny Tremblay | R10: Shanny Tremblay handles all logistics for Nucleom/Nortech staff
A11: May | B11: MED | C11: T&D Conference | D11: May 4-7 | E11: Chicago IL | F11: Powerline | G11: 2 | H11: Math · Sha | I11: — | J11: 3 | K11: 18000 | L11: Not Started | M11: Pending | O11: =IF(M11="Approved",K11,IF(M11="Rejected",-K11,IF(M11="On Hold",K11,0))) -> 0 | P11: BU Services | Q11: Shanny Tremblay | R11: Shanny Tremblay handles all logistics for Nucleom/Nortech staff
B12: MED | C12: CIM Vancouver | D12: May 4-6 | E12: Vancouver BC | F12: Mining NDT | G12: 2 | H12: Vinoth · Max | I12: — | J12: 2 | K12: 9000 | L12: Not Started | M12: Pending | O12: =IF(M12="Approved",K12,IF(M12="Rejected",-K12,IF(M12="On Hold",K12,0))) -> 0 | P12: BU Services | Q12: Shanny Tremblay | R12: Shanny Tremblay handles all logistics for Nucleom/Nortech staff
A13: June | B13: HIGH | C13: ECNDT Verona | D13: Jun 15-19 | E13: Verona Italy | F13: All Initiatives | G13: 5 | H13: Xavier · Guillaume · Lucy · Hervé · Fabian | I13: ✓ | J13: 5 | K13: 72000 | L13: Not Started | M13: Pending | O13: =IF(M13="Approved",K13,IF(M13="Rejected",-K13,IF(M13="On Hold",K13,0))) -> 0 | P13: Joint | Q13: Ekoscan + Shanny Tremblay | R13: Coordinate between Ekoscan team and Shanny Tremblay
B14: MED | C14: Canadian Mining Expo | D14: Jun 9-11 | E14: Timmins ON | F14: Mining NDT | G14: 2 | H14: Keith · Speaker | I14: ✓ | J14: 3 | K14: 18000 | L14: Not Started | M14: Pending | O14: =IF(M14="Approved",K14,IF(M14="Rejected",-K14,IF(M14="On Hold",K14,0))) -> 0 | P14: BU Services | Q14: Shanny Tremblay | R14: Shanny Tremblay handles all logistics for Nucleom/Nortech staff
A15: July | B15: HIGH | C15: API Inspection Summit | D15: Jul 20-23 | E15: San Antonio TX | F15: Pipeline DA · 3X | G15: 3 | H15: Keith · Tim · Alex | I15: ✓ | J15: 5 | K15: 42000 | L15: Not Started | M15: Pending | O15: =IF(M15="Approved",K15,IF(M15="Rejected",-K15,IF(M15="On Hold",K15,0))) -> 0 | P15: BU Services | Q15: Shanny Tremblay | R15: Shanny Tremblay handles all logistics for Nucleom/Nortech staff
A16: August | B16: MED | C16: Cigre Paris | D16: Aug 23-28 | E16: Paris France | F16: Powerline | G16: 2 | H16: Math +1 | I16: — | J16: 3 | K16: 28000 | L16: Not Started | M16: Pending | O16: =IF(M16="Approved",K16,IF(M16="Rejected",-K16,IF(M16="On Hold",K16,0))) -> 0 | P16: BU Services | Q16: Shanny Tremblay | R16: Shanny Tremblay handles all logistics for Nucleom/Nortech staff
A17: September | B17: HIGH | C17: IPC Pipeline Conf. | D17: Sep 21-25 | E17: Calgary AB | F17: Pipeline DA | G17: 2 | H17: Max · Vinoth | I17: ✓ | J17: 5 | K17: 32000 | L17: Not Started | M17: Pending | O17: =IF(M17="Approved",K17,IF(M17="Rejected",-K17,IF(M17="On Hold",K17,0))) -> 0 | P17: BU Services | Q17: Shanny Tremblay | R17: Shanny Tremblay handles all logistics for Nucleom/Nortech staff
B18: HIGH | C18: IPCE Pipeline Expo | D18: Sep 22-24 | E18: Calgary AB | F18: Pipeline DA | G18: 2 | H18: Vincent Ribouleau | I18: ✓ | J18: 3 | K18: 26000 | L18: Not Started | M18: Pending | O18: =IF(M18="Approved",K18,IF(M18="Rejected",-K18,IF(M18="On Hold",K18,0))) -> 0 | P18: BU Services | Q18: Shanny Tremblay | R18: Shanny Tremblay handles all logistics for Nucleom/Nortech staff
B19: MED | C19: CEN CAN Expo | D19: Sep 9-10 | E19: Thunder Bay ON | F19: Mining NDT | G19: 2 | H19: TBD ×2 | I19: ✓ | J19: 2 | K19: 12000 | L19: Not Started | M19: Pending | O19: =IF(M19="Approved",K19,IF(M19="Rejected",-K19,IF(M19="On Hold",K19,0))) -> 0 | P19: BU Services | Q19: Shanny Tremblay | R19: Shanny Tremblay handles all logistics for Nucleom/Nortech staff
A20: October | B20: HIGH | C20: ASNT 2026 | D20: Oct 12-15 | E20: Columbus OH | F20: Mining NDT | G20: 4 | H20: TBD ×4 | I20: ✓ | J20: 5 | K20: 68000 | L20: Not Started | M20: Pending | O20: =IF(M20="Approved",K20,IF(M20="Rejected",-K20,IF(M20="On Hold",K20,0))) -> 0 | P20: Joint | Q20: Ekoscan + Shanny Tremblay | R20: Coordinate between Ekoscan team and Shanny Tremblay
B21: MED-H | C21: API Storage Tank Expo | D21: Oct 19-22 | E21: Austin TX | F21: Pipeline DA · 3X | G21: 2 | H21: Keith · Tim | I21: ✓ | J21: 4 | K21: 36000 | L21: Not Started | M21: Pending | O21: =IF(M21="Approved",K21,IF(M21="Rejected",-K21,IF(M21="On Hold",K21,0))) -> 0 | P21: BU Services | Q21: Shanny Tremblay | R21: Shanny Tremblay handles all logistics for Nucleom/Nortech staff
A22: November | B22: MED-H | C22: API Insp. Summit (EIG) | D22: Nov TBC | E22: San Antonio TX | F22: Pipeline DA | G22: 2 | H22: TBD — coordinate w/ Ekoscan | I22: ✓ | J22: 4 | K22: 32000 | L22: Not Started | M22: Pending | O22: =IF(M22="Approved",K22,IF(M22="Rejected",-K22,IF(M22="On Hold",K22,0))) -> 0 | P22: Ekoscan BU | Q22: Ekoscan Logistics Team | R22: Ekoscan manages logistics — Shanny NOT responsible
A23: Ongoing | B23: HIGH | C23: COFREND Lyon | D23: May 19-21 | E23: Lyon France | F23: Base Business | G23: 6 | H23: Guillaume N · Guillaume P + team | I23: ✓ | J23: 4 | K23: 58000 | L23: Not Started | M23: Pending | O23: =IF(M23="Approved",K23,IF(M23="Rejected",-K23,IF(M23="On Hold",K23,0))) -> 0 | P23: Ekoscan BU | Q23: Ekoscan Logistics Team | R23: Ekoscan manages logistics — Shanny NOT responsible
A24: TOTAL — 19 conferences · 59 person-attendances | K24: =SUM(K5:K23) -> 644000
A25: APPROVED BUDGET | M25: =SUMIF(M5:M23,"Approved",K5:K23) -> 0 | S25: =SUMIF(M5:M23,"Approved",S5:S23) -> 0
A26: ON HOLD BUDGET | M26: =SUMIF(M5:M23,"On Hold",K5:K23) -> 0 | S26: =SUMIF(M5:M23,"On Hold",S5:S23) -> 0
A27: REJECTED BUDGET | M27: =SUMIF(M5:M23,"Rejected",K5:K23) -> 0 | S27: =SUMIF(M5:M23,"Rejected",S5:S23) -> 0
A28: PENDING BUDGET | M28: =SUMIF(M5:M23,"Pending",K5:K23) -> 644000 | S28: =SUMIF(M5:M23,"Pending",S5:S23) -> 0
A30: HOW TO USE: Open the HTML Conference Action Plan portal in Chrome → review each conference card → click ✓ Approve, ⏸ Hold, or ✗ Reject. Click 'Export Approvals' → copy → paste Jon's notes into Col N here. Change Col M dropdown to match decisions. Budget totals update automatically. Conditional formatting shows green/amber/red by status.
A31: ★ SHANNY'S JOB: After each BU Services conference → open this file → find the conference row → enter the total actual cost (from invoices) into Col S (Total Actual). Col S is the master cost record for the Command Centre and Jeremy's quarterly review. The detailed cost breakdown (flights/hotels/booth etc.) goes in Action Tracker tab Col J. NOT responsible for: PPIM · NDTMA · AMPP · COFREND · API Insp. Summit (EIG) — these are Ekoscan BU shows.

Sheet Attendee Action Plan
A1: BU SERVICES — 2026 CONFERENCE ATTENDEE ACTION PLAN · LEADS & OPPORTUNITIES
A3: Track every lead, opportunity, and follow-up from every conference. Enter within 48h of return. Mandatory: Salesforce entry + BU_Initiative__c tag for every row. Nucleom/Nortech staff ONLY — Shanny Tremblay coordinates BU Services shows.
A4: Lead Quality: | B4: HOT | C4: WARM | D4: COLD | F4: Opp Stage: | G4: Qualifying | H4: Proposing | I4: Negotiating | J4: Won ✓ | K4: Lost ✗
A6: Conference | B6: Dates | C6: Location | D6: Initiative | E6: Attendee (Our Person) | F6: Contact Name (Lead/Prospect) | G6: Title / Company | H6: Lead Source | I6: Lead Quality | J6: Initiative Tag | K6: Opp Created? | L6: Opp Value (CAD est.) | M6: Opp Stage | N6: Follow-up Date | O6: Follow-up Owner | P6: Follow-up Done? | Q6: Salesforce Entry | R6: Notes / Context
A7: IPEIA 2026 ⭐ · Mar 10-12 · Calgary AB · All Initiatives · HIGH · Logistics: BU Services
A8: IPEIA 2026 ⭐ | B8: Mar 10-12 | C8: Calgary AB | D8: All Initiatives | E8: Max Aggrey | H8: IPEIA 2026 ⭐ Booth | J8: All Initiatives | K8: TBD | O8: Max Aggrey | P8: Pending | Q8: Pending
A9: IPEIA 2026 ⭐ | B9: Mar 10-12 | C9: Calgary AB | D9: All Initiatives | E9: Keith | H9: IPEIA 2026 ⭐ Booth | J9: All Initiatives | K9: TBD | O9: Keith | P9: Pending | Q9: Pending
A10: IPEIA 2026 ⭐ | B10: Mar 10-12 | C10: Calgary AB | D10: All Initiatives | E10: Tim | H10: IPEIA 2026 ⭐ Booth | J10: All Initiatives | K10: TBD | O10: Tim | P10: Pending | Q10: Pending
A11: IPEIA 2026 ⭐ | B11: Mar 10-12 | C11: Calgary AB | D11: All Initiatives | E11: Alex Cyr | H11: IPEIA 2026 ⭐ Booth | J11: All Initiatives | K11: TBD | O11: Alex Cyr | P11: Pending | Q11: Pending
A12: IPEIA 2026 ⭐ | B12: Mar 10-12 | C12: Calgary AB | D12: All Initiatives | E12: Rick Carlton | H12: IPEIA 2026 ⭐ Booth | J12: All Initiatives | K12: TBD | O12: Rick Carlton | P12: Pending | Q12: Pending
A13: IPEIA 2026 ⭐ | B13: Mar 10-12 | C13: Calgary AB | D13: All Initiatives | E13: Marcos | H13: IPEIA 2026 ⭐ Booth | J13: All Initiatives | K13: TBD | O13: Marcos | P13: Pending | Q13: Pending
A14: ↳ Add rows here for additional contacts met at this conference
A16: CNA 2026 · Apr 28-30 · Ottawa ON · Nuclear/OPG · HIGH · Logistics: BU Services
A17: CNA 2026 | B17: Apr 28-30 | C17: Ottawa ON | D17: Nuclear/OPG | E17: Olivier Marcotte | H17: CNA 2026 Booth | J17: Nuclear/OPG | K17: TBD | O17: Olivier Marcotte | P17: Pending | Q17: Pending
A18: CNA 2026 | B18: Apr 28-30 | C18: Ottawa ON | D18: Nuclear/OPG | E18: Jon Eustace | H18: CNA 2026 Booth | J18: Nuclear/OPG | K18: TBD | O18: Jon Eustace | P18: Pending | Q18: Pending
A19: CNA 2026 | B19: Apr 28-30 | C19: Ottawa ON | D19: Nuclear/OPG | E19: Louis-Pierre Théberge | H19: CNA 2026 Booth | J19: Nuclear/OPG | K19: TBD | O19: Louis-Pierre Théberge | P19: Pending | Q19: Pending
A20: CNA 2026 | B20: Apr 28-30 | C20: Ottawa ON | D20: Nuclear/OPG | E20: Shanny Tremblay | H20: CNA 2026 Booth | J20: Nuclear/OPG | K20: TBD | O20: Shanny Tremblay | P20: Pending | Q20: Pending
A21: ↳ Add rows here for additional contacts met at this conference
A23: T&D Conference · May 4-7 · Chicago IL · Powerline · MED · Logistics: BU Services
A24: T&D Conference | B24: May 4-7 | C24: Chicago IL | D24: Powerline | E24: Mathieu Beauchesne | H24: T&D Conference Booth | J24: Powerline | K24: TBD | O24: Mathieu Beauchesne | P24: Pending | Q24: Pending
A25: T&D Conference | B25: May 4-7 | C25: Chicago IL | D25: Powerline | E25: Shanny Tremblay | H25: T&D Conference Booth | J25: Powerline | K25: TBD | O25: Shanny Tremblay | P25: Pending | Q25: Pending
A26: ↳ Add rows here for additional contacts met at this conference
A28: CIM Vancouver · May 4-6 · Vancouver BC · Mining NDT · MED · Logistics: BU Services
A29: CIM Vancouver | B29: May 4-6 | C29: Vancouver BC | D29: Mining NDT | E29: Vinoth Tharma | H29: CIM Vancouver Booth | J29: Mining NDT | K29: TBD | O29: Vinoth Tharma | P29: Pending | Q29: Pending
A30: CIM Vancouver | B30: May 4-6 | C30: Vancouver BC | D30: Mining NDT | E30: Max Aggrey | H30: CIM Vancouver Booth | J30: Mining NDT | K30: TBD | O30: Max Aggrey | P30: Pending | Q30: Pending
A31: ↳ Add rows here for additional contacts met at this conference
A33: Canadian Mining Expo · Jun 9-11 · Timmins ON · Mining NDT · MED · Logistics: BU Services
A34: Canadian Mining Expo | B34: Jun 9-11 | C34: Timmins ON | D34: Mining NDT | E34: Keith | H34: Canadian Mining Expo Booth | J34: Mining NDT | K34: TBD | O34: Keith | P34: Pending | Q34: Pending
A35: Canadian Mining Expo | B35: Jun 9-11 | C35: Timmins ON | D35: Mining NDT | E35: TBD Speaker | H35: Canadian Mining Expo Booth | J35: Mining NDT | K35: TBD | O35: TBD Speaker | P35: Pending | Q35: Pending
A36: ↳ Add rows here for additional contacts met at this conference
A38: ECNDT Verona · Jun 15-19 · Verona Italy · All Initiatives · HIGH · Logistics: Joint
A39: ECNDT Verona | B39: Jun 15-19 | C39: Verona Italy | D39: All Initiatives | E39: Xavier | H39: ECNDT Verona Booth | J39: All Initiatives | K39: TBD | O39: Xavier | P39: Pending | Q39: Pending
A40: ECNDT Verona | B40: Jun 15-19 | C40: Verona Italy | D40: All Initiatives | E40: Guillaume N | H40: ECNDT Verona Booth | J40: All Initiatives | K40: TBD | O40: Guillaume N | P40: Pending | Q40: Pending
A41: ECNDT Verona | B41: Jun 15-19 | C41: Verona Italy | D41: All Initiatives | E41: Lucy | H41: ECNDT Verona Booth | J41: All Initiatives | K41: TBD | O41: Lucy | P41: Pending | Q41: Pending
A42: ECNDT Verona | B42: Jun 15-19 | C42: Verona Italy | D42: All Initiatives | E42: Hervé | H42: ECNDT Verona Booth | J42: All Initiatives | K42: TBD | O42: Hervé | P42: Pending | Q42: Pending
A43: ECNDT Verona | B43: Jun 15-19 | C43: Verona Italy | D43: All Initiatives | E43: Fabian | H43: ECNDT Verona Booth | J43: All Initiatives | K43: TBD | O43: Fabian | P43: Pending | Q43: Pending
A44: ↳ Add rows here for additional contacts met at this conference
A46: API Inspection Summit · Jul 20-23 · San Antonio TX · Pipeline DA · HIGH · Logistics: BU Services
A47: API Inspection Summit | B47: Jul 20-23 | C47: San Antonio TX | D47: Pipeline DA | E47: Keith | H47: API Inspection Summit Booth | J47: Pipeline DA | K47: TBD | O47: Keith | P47: Pending | Q47: Pending
A48: API Inspection Summit | B48: Jul 20-23 | C48: San Antonio TX | D48: Pipeline DA | E48: Tim | H48: API Inspection Summit Booth | J48: Pipeline DA | K48: TBD | O48: Tim | P48: Pending | Q48: Pending
...
